Workbook

Sheet Instructions
A1: Study extraction workbook — FS for ML-based IoT IDS SLR
A2: Fill only the yellow cells (blue text). Grey/white cells are formulas — do not edit.
A3: Completed workbook: 130 included studies. Primary FS family was coded manually from title/abstract; other fields were extracted with keyword rules from full texts (see Methods).
A4: 2. Studies: one row per included study (S001–S130). Y/N columns use drop-downs.
A5: 3. QA: score each study on QA1–QA8 (1 = yes, 0.5 = partly, 0 = no). Total and grade are automatic.
A6: 4. Checklist: mark each study Y/N on the 12 FS-IDS-RC items.
A7: 5. DRL: pick each study's deployment-readiness level (DRL-0 … DRL-4).
A8: 6. Summary: all numbers needed for the paper's TBD cells are calculated here.
A10: Example of a completed Studies row (format only — verify against the paper before use):
A12: ID | B12: Authors | C12: Year | D12: Title | E12: Venue | F12: Venue type | G12: DOI | H12: Filter | I12: Wrapper (sequential) | J12: Wrapper (metaheuristic) | K12: Embedded | L12: Hybrid | M12: Transformation (PCA/AE) | N12: Primary FS family | O12: FS algorithm(s) | P12: Fitness / criterion | Q12: Classifier(s) | R12: Deep learning used | S12: Dataset(s) | T12: No. of datasets | U12: Legacy/non-IoT dataset only | V12: Cross-dataset test | W12: Class setting | X12: Original features | Y12: Selected features | Z12: Reduction (%) | AA12: Validation protocol | AB12: FS fitted on training data only | AC12: Repeated runs (stochastic FS) | AD12: Baseline without FS | AE12: Best reported accuracy (%) | AF12: Accuracy > 99% | AG12: FAR reported | AH12: Macro/per-class F1 reported | AI12: Statistical test | AJ12: FS time reported | AK12: Inference latency reported | AL12: Memory reported | AM12: Energy reported | AN12: Edge/IoT hardware used | AO12: Concept drift addressed | AP12: Adversarial robustness tested | AQ12: XAI used | AR12: XAI used for selection | AS12: Code/data available | AT12: Author-stated limitations | AU12: Notes
A13: EX | B13: Kasongo & Sun | C13: 2020 | D13: Performance analysis of IDS using a feature selection method on the UNSW-NB15 dataset | E13: Journal of Big Data | F13: Journal | K13: Y | N13: Embedded | O13: XGBoost importance | Q13: ANN, kNN, DT, LR, SVM | S13: UNSW-NB15 | T13: 1 | W13: Both | AG13: N
A14: Values above are illustrative; check every field against the original paper.

Sheet Summary
A1: Paper item | B1: Value | C1: Where it goes in the paper
A2: Studies entered | B2: =COUNTA(Studies!$D$2:$D$131) -> 130 | C2: Included studies
A3: Earliest publication year | B3: =MIN(Studies!$C$2:$C$131) -> 2019 | C3: Abstract / Sec. 4.1
A4: Latest publication year | B4: =MAX(Studies!$C$2:$C$131) -> 2025 | C4: Abstract / Sec. 4.1
A5: Journal articles (%) | B5: =IFERROR(COUNTIF(Studies!$F$2:$F$131,"Journal")/COUNTA(Studies!$D$2:$D$131),"") -> 1 | C5: Sec. 4.1
A6: Conference papers (%) | B6: =IFERROR(COUNTIF(Studies!$F$2:$F$131,"Conference")/COUNTA(Studies!$D$2:$D$131),"") -> 0 | C6: Sec. 4.1
A7: QA grade: High (n) | B7: =COUNTIF(QA!$K$2:$K$131,"High") -> 22 | C7: Sec. 4.1
A8: QA grade: Medium (n) | B8: =COUNTIF(QA!$K$2:$K$131,"Medium") -> 49 | C8: Sec. 4.1
A9: QA grade: Low (n) | B9: =COUNTIF(QA!$K$2:$K$131,"Low") -> 59 | C9: Sec. 4.1
A10: Filter studies (n) | B10: =COUNTIF(Studies!$H$2:$H$131,"Y") -> 81 | C10: Table 5
A11: Filter studies (%) | B11: =IFERROR(COUNTIF(Studies!$H$2:$H$131,"Y")/COUNTA(Studies!$D$2:$D$131),"") -> 0.62307692 | C11: Table 5
A12: Wrapper (sequential) studies (n) | B12: =COUNTIF(Studies!$I$2:$I$131,"Y") -> 26 | C12: Table 5
A13: Wrapper (sequential) studies (%) | B13: =IFERROR(COUNTIF(Studies!$I$2:$I$131,"Y")/COUNTA(Studies!$D$2:$D$131),"") -> 0.2 | C13: Table 5
A14: Wrapper (metaheuristic) studies (n) | B14: =COUNTIF(Studies!$J$2:$J$131,"Y") -> 99 | C14: Table 5
A15: Wrapper (metaheuristic) studies (%) | B15: =IFERROR(COUNTIF(Studies!$J$2:$J$131,"Y")/COUNTA(Studies!$D$2:$D$131),"") -> 0.76153846 | C15: Table 5
A16: Embedded studies (n) | B16: =COUNTIF(Studies!$K$2:$K$131,"Y") -> 33 | C16: Table 5
A17: Embedded studies (%) | B17: =IFERROR(COUNTIF(Studies!$K$2:$K$131,"Y")/COUNTA(Studies!$D$2:$D$131),"") -> 0.25384615 | C17: Table 5
A18: Hybrid studies (n) | B18: =COUNTIF(Studies!$L$2:$L$131,"Y") -> 39 | C18: Table 5
A19: Hybrid studies (%) | B19: =IFERROR(COUNTIF(Studies!$L$2:$L$131,"Y")/COUNTA(Studies!$D$2:$D$131),"") -> 0.3 | C19: Table 5
A20: Transformation (PCA/AE) studies (n) | B20: =COUNTIF(Studies!$M$2:$M$131,"Y") -> 70 | C20: Table 5
A21: Transformation (PCA/AE) studies (%) | B21: =IFERROR(COUNTIF(Studies!$M$2:$M$131,"Y")/COUNTA(Studies!$D$2:$D$131),"") -> 0.53846154 | C21: Table 5
A22: Filter: median reduction (%) | B22: {=IFERROR(MEDIAN(IF((Studies!$N$2:$N$131="Filter")*ISNUMBER(Studies!$Z$2:$Z$131),Studies!$Z$2:$Z$131)),"")} -> 0.40372671 | C22: Table 7
A23: Filter: studies – report FAR (n) | B23: =COUNTIFS(Studies!$N$2:$N$131,"Filter",Studies!$AG$2:$AG$131,"Y") -> 5 | C23: Table 7
A24: Filter: studies – report cost (n) | B24: =COUNTIFS(Studies!$N$2:$N$131,"Filter",Studies!$AK$2:$AK$131,"Y") -> 12 | C24: Table 7
A25: Filter: studies – cross-dataset test (n) | B25: =COUNTIFS(Studies!$N$2:$N$131,"Filter",Studies!$V$2:$V$131,"Y") -> 0 | C25: Table 7
A26: Wrapper/metaheuristic: median reduction (%) | B26: {=IFERROR(MEDIAN(IF((Studies!$N$2:$N$131="Wrapper-meta")*ISNUMBER(Studies!$Z$2:$Z$131),Studies!$Z$2:$Z$131)),"")} -> 0.6875 | C26: Table 7
A27: Wrapper/metaheuristic: studies – report FAR (n) | B27: =COUNTIFS(Studies!$N$2:$N$131,"Wrapper-meta",Studies!$AG$2:$AG$131,"Y") -> 33 | C27: Table 7
A28: Wrapper/metaheuristic: studies – report cost (n) | B28: =COUNTIFS(Studies!$N$2:$N$131,"Wrapper-meta",Studies!$AK$2:$AK$131,"Y") -> 24 | C28: Table 7
A29: Wrapper/metaheuristic: studies – cross-dataset test (n) | B29: =COUNTIFS(Studies!$N$2:$N$131,"Wrapper-meta",Studies!$V$2:$V$131,"Y") -> 8 | C29: Table 7
A30: Embedded: median reduction (%) | B30: {=IFERROR(MEDIAN(IF((Studies!$N$2:$N$131="Embedded")*ISNUMBER(Studies!$Z$2:$Z$131),Studies!$Z$2:$Z$131)),"")} -> 0.7118863 | C30: Table 7
A31: Embedded: studies – report FAR (n) | B31: =COUNTIFS(Studies!$N$2:$N$131,"Embedded",Studies!$AG$2:$AG$131,"Y") -> 4 | C31: Table 7
A32: Embedded: studies – report cost (n) | B32: =COUNTIFS(Studies!$N$2:$N$131,"Embedded",Studies!$AK$2:$AK$131,"Y") -> 10 | C32: Table 7
A33: Embedded: studies – cross-dataset test (n) | B33: =COUNTIFS(Studies!$N$2:$N$131,"Embedded",Studies!$V$2:$V$131,"Y") -> 0 | C33: Table 7
A34: Hybrid: median reduction (%) | B34: {=IFERROR(MEDIAN(IF((Studies!$N$2:$N$131="Hybrid")*ISNUMBER(Studies!$Z$2:$Z$131),Studies!$Z$2:$Z$131)),"")} -> 0.375 | C34: Table 7
A35: Hybrid: studies – report FAR (n) | B35: =COUNTIFS(Studies!$N$2:$N$131,"Hybrid",Studies!$AG$2:$AG$131,"Y") -> 13 | C35: Table 7
A36: Hybrid: studies – report cost (n) | B36: =COUNTIFS(Studies!$N$2:$N$131,"Hybrid",Studies!$AK$2:$AK$131,"Y") -> 9 | C36: Table 7
A37: Hybrid: studies – cross-dataset test (n) | B37: =COUNTIFS(Studies!$N$2:$N$131,"Hybrid",Studies!$V$2:$V$131,"Y") -> 3 | C37: Table 7
A38: Overall median reduction (%) | B38: =IFERROR(MEDIAN(Studies!$Z$2:$Z$131),"") -> 0.58928571 | C38: Sec. 4.3
A39: Reduction IQR lower (%) | B39: =IFERROR(QUARTILE(Studies!$Z$2:$Z$131,1),"") -> 0.33404874 | C39: Sec. 4.3
A40: Reduction IQR upper (%) | B40: =IFERROR(QUARTILE(Studies!$Z$2:$Z$131,3),"") -> 0.80731707 | C40: Sec. 4.3
...

Sheet Studies
A1: ID | B1: Authors | C1: Year | D1: Title | E1: Venue | F1: Venue type | G1: DOI | H1: Filter (mentioned) | I1: Wrapper (sequential) (mentioned) | J1: Wrapper (metaheuristic) (mentioned) | K1: Embedded (mentioned) | L1: Hybrid (mentioned) | M1: Transformation (PCA/AE) (mentioned) | N1: Primary FS family | O1: FS algorithm(s) | P1: Fitness / criterion | Q1: Classifier(s) | R1: Deep learning used | S1: Dataset(s) | T1: No. of datasets | U1: Legacy/non-IoT dataset only | V1: Cross-dataset test | W1: Class setting | X1: Original features | Y1: Selected features | Z1: Reduction (%) | AA1: Validation protocol | AB1: FS fitted on training data only | AC1: Repeated runs (stochastic FS) | AD1: Baseline without FS | AE1: Best reported accuracy (%) | AF1: Accuracy > 99% | AG1: FAR reported | AH1: Macro/per-class F1 reported | AI1: Statistical test | AJ1: FS time reported | AK1: Inference latency reported | AL1: Memory reported | AM1: Energy reported | AN1: Edge/IoT hardware used | AO1: Concept drift addressed | AP1: Adversarial robustness tested | AQ1: XAI used | AR1: XAI used for selection | AS1: Code/data available | AT1: Author-stated limitations | AU1: Notes
A2: S001 | B2: Mr.B. Suresh; M. Venkatachalam; Dr.M. Saroja | C2: 2019 | D2: Towards Improved Random Forest based Feature Selection for Intrusion Detection in Smart IOT Environment | E2: International Journal of Innovative Technology and Exploring Engineering | F2: Journal | G2: 10.35940/ijitee.f1446.0981119 | H2: Y | I2: N | J2: Y | K2: N | L2: N | M2: N | N2: Embedded | Q2: RF, DT, kNN | R2: N | S2: Kaggle (unspecified) | T2: 1 | U2: N | V2: N | Z2: =IF(AND(ISNUMBER(X2),ISNUMBER(Y2),X2>0),1-Y2/X2,"") | AA2: Not stated | AB2: Unclear | AC2: N | AD2: N | AF2: =IF(ISNUMBER(AE2),IF(AE2>99,"Y","N"),"") | AG2: Y | AH2: N | AI2: N | AJ2: N | AK2: N | AL2: N | AM2: N | AN2: N | AO2: N | AP2: N | AQ2: N | AR2: N | AS2: N | AU2: rec_id R0042
A3: S002 | B3: Azam Davahli; Mahboubeh Shamsi; Golnoush Abaei | C3: 2020 | D3: A Lightweight Anomaly Detection Model using SVM for WSNs in IoT through a Hybrid Feature Selection Algorithm based on GA and GWO | F3: Journal | G3: 10.22108/jcs.2020.119468.1033 | H3: N | I3: N | J3: Y | K3: N | L3: Y | M3: N | N3: Hybrid | Q3: SVM, kNN, MLP/ANN/DNN | R3: N | S3: AWID | T3: 1 | U3: Y | V3: N | W3: Binary | Z3: =IF(AND(ISNUMBER(X3),ISNUMBER(Y3),X3>0),1-Y3/X3,"") | AA3: k-fold CV | AB3: Unclear | AC3: N | AD3: N | AF3: =IF(ISNUMBER(AE3),IF(AE3>99,"Y","N"),"") | AG3: Y | AH3: N | AI3: N | AJ3: Y | AK3: Y | AL3: N | AM3: N | AN3: N | AO3: N | AP3: N | AQ3: N | AR3: N | AS3: N | AU3: rec_id R0047
A4: S003 | B4: J. Pokala; B. Lalitha | C4: 2021 | D4: A Novel Intrusion Detection System for RPL Based IoT Networks with Bio-Inspired Feature Selection and Ensemble Classifier | F4: Journal | G4: 10.21203/rs.3.rs-442429/v1 | H4: Y | I4: N | J4: Y | K4: N | L4: Y | M4: N | N4: Wrapper-meta | Q4: SVM, DT, kNN, LR, AdaBoost, LSTM/GRU/RNN | R4: Y | S4: KDD Cup 99 | T4: 1 | U4: Y | V4: N | Z4: =IF(AND(ISNUMBER(X4),ISNUMBER(Y4),X4>0),1-Y4/X4,"") | AA4: k-fold CV | AB4: Unclear | AC4: N | AD4: Y | AE4: 96.4 | AF4: =IF(ISNUMBER(AE4),IF(AE4>99,"Y","N"),"") -> N | AG4: Y | AH4: Y | AI4: N | AJ4: Y | AK4: N | AL4: N | AM4: N | AN4: N | AO4: N | AP4: N | AQ4: N | AR4: N | AS4: N | AU4: rec_id R0103
A5: S004 | B5: Alok Kumar Pani | C5: 2021 | D5: An efficient algorithmic technique for feature selection in IoT based intrusion detection system | E5: Indian Journal of Science and Technology | F5: Journal | G5: 10.17485/ijst/v14i1.2057 | H5: Y | I5: N | J5: Y | K5: N | L5: N | M5: N | N5: Wrapper-meta | Q5: RF, SVM, DT, LR, MLP/ANN/DNN | R5: Y | S5: DS2OS | T5: 1 | U5: N | V5: N | W5: Binary | Z5: =IF(AND(ISNUMBER(X5),ISNUMBER(Y5),X5>0),1-Y5/X5,"") | AA5: Not stated | AB5: Unclear | AC5: N | AD5: N | AE5: 99.5 | AF5: =IF(ISNUMBER(AE5),IF(AE5>99,"Y","N"),"") -> Y | AG5: Y | AH5: N | AI5: N | AJ5: Y | AK5: N | AL5: N | AM5: N | AN5: N | AO5: N | AP5: N | AQ5: N | AR5: N | AS5: N | AU5: rec_id R0125
A6: S005 | B6: Bello Nazifi Kagara | C6: 2021 | D6: Comparative Study on Feature Selection Techniques in Intrusion Detection Systems using Ensemble Classifiers | E6: International Journal of Innovative Computing | F6: Journal | G6: 10.11113/ijic.v11n1.286 | H6: Y | I6: N | J6: Y | K6: N | L6: N | M6: Y | N6: Hybrid | Q6: SVM, LR | R6: N | S6: KDD Cup 99 | T6: 1 | U6: Y | V6: N | Z6: =IF(AND(ISNUMBER(X6),ISNUMBER(Y6),X6>0),1-Y6/X6,"") | AA6: Not stated | AB6: Unclear | AC6: N | AD6: N | AE6: 99.7 | AF6: =IF(ISNUMBER(AE6),IF(AE6>99,"Y","N"),"") -> Y | AG6: Y | AH6: Y | AI6: N | AJ6: Y | AK6: N | AL6: N | AM6: N | AN6: N | AO6: N | AP6: N | AQ6: N | AR6: N | AS6: N | AU6: rec_id R0136
A7: S006 | B7: Gozde Karatas Baydoğmus | C7: 2021 | D7: Detecting Internet of Things Attacks by Using Hybrid Learning and Feature Selection Method | E7: European Journal of Science and Technology | F7: Journal | G7: 10.31590/ejosat.1017433 | H7: Y | I7: N | J7: N | K7: Y | L7: Y | M7: N | N7: Filter | Q7: DT, CNN, LSTM/GRU/RNN | R7: Y | S7: Bot-IoT, TON_IoT | T7: 2 | U7: N | V7: N | X7: 119 | Y7: 115 | Z7: =IF(AND(ISNUMBER(X7),ISNUMBER(Y7),X7>0),1-Y7/X7,"") -> 0.033613445 | AA7: Not stated | AB7: Unclear | AC7: N | AD7: N | AE7: 99.99 | AF7: =IF(ISNUMBER(AE7),IF(AE7>99,"Y","N"),"") -> Y | AG7: N | AH7: N | AI7: Y | AJ7: Y | AK7: Y | AL7: N | AM7: N | AN7: N | AO7: N | AP7: N | AQ7: N | AR7: N | AS7: N | AU7: rec_id R0140
A8: S007 | B8: Maheshi Buddhinee Dissanayake | C8: 2021 | D8: Feature Engineering for Cyber-attack detection in Internet of Things | E8: International Journal of Wireless and Microwave Technologies | F8: Journal | G8: 10.5815/ijwmt.2021.06.05 | H8: N | I8: N | J8: N | K8: Y | L8: N | M8: Y | N8: Embedded | Q8: RF, DT, LightGBM, AdaBoost, MLP/ANN/DNN | R8: Y | S8: KDD Cup 99 | T8: 1 | U8: Y | V8: N | W8: Multi-class | Y8: 10 | Z8: =IF(AND(ISNUMBER(X8),ISNUMBER(Y8),X8>0),1-Y8/X8,"") | AA8: k-fold CV | AB8: Unclear | AC8: N | AD8: Y | AE8: 99 | AF8: =IF(ISNUMBER(AE8),IF(AE8>99,"Y","N"),"") -> N | AG8: N | AH8: N | AI8: N | AJ8: Y | AK8: Y | AL8: N | AM8: N | AN8: N | AO8: N | AP8: N | AQ8: N | AR8: N | AS8: N | AU8: rec_id R0151
A9: S008 | B9: G. Kavitha; N. M. Elango | C9: 2021 | D9: Genetic Algorithm-Conditional Mutual Information Maximization based feature selection for Bot Attack Classification in IoT devices | E9: Journal of Mobile Multimedia | F9: Journal | G9: 10.13052/jmm1550-4646.1816 | H9: Y | I9: Y | J9: Y | K9: N | L9: Y | M9: Y | N9: Hybrid | Q9: SVM, DT, NB | R9: N | S9: Private/unspecified | T9: 1 | U9: Y | V9: N | W9: Both | Z9: =IF(AND(ISNUMBER(X9),ISNUMBER(Y9),X9>0),1-Y9/X9,"") | AA9: k-fold CV | AB9: Unclear | AC9: N | AD9: N | AE9: 99.87 | AF9: =IF(ISNUMBER(AE9),IF(AE9>99,"Y","N"),"") -> Y | AG9: Y | AH9: N | AI9: N | AJ9: Y | AK9: N | AL9: Y | AM9: N | AN9: N | AO9: N | AP9: N | AQ9: N | AR9: N | AS9: N | AU9: rec_id R0157
A10: S009 | B10: Rawaa Ismael Farhan; Abeer Tariq Maolood; Nidaa Falih Hassan | C10: 2021 | D10: Hybrid Feature Selection Approach to Improve the Deep Neural Network on New Flow-Based Dataset for NIDS | E10: Wasit Journal of Computer and Mathematics Science | F10: Journal | G10: 10.31185/wjcm.vol1.iss1.10 | H10: Y | I10: N | J10: Y | K10: N | L10: Y | M10: Y | N10: Hybrid | Q10: RF, SVM, MLP/ANN/DNN, CNN, LSTM/GRU/RNN | R10: Y | S10: NSL-KDD, CSE-CIC-IDS2018 | T10: 2 | U10: Y | V10: N | W10: Both | Z10: =IF(AND(ISNUMBER(X10),ISNUMBER(Y10),X10>0),1-Y10/X10,"") | AA10: k-fold CV | AB10: Unclear | AC10: N | AD10: Y | AE10: 95 | AF10: =IF(ISNUMBER(AE10),IF(AE10>99,"Y","N"),"") -> N | AG10: Y | AH10: Y | AI10: N | AJ10: Y | AK10: Y | AL10: N | AM10: N | AN10: N | AO10: N | AP10: N | AQ10: N | AR10: N | AS10: N | AU10: rec_id R0158
A11: S010 | B11: Taifeng Pan | C11: 2021 | D11: Intrusion Detection Method of Internet of Things Based on Multi GBDT Feature Dimensionality Reduction and Hierarchical Traffic Detection | E11: Journal of Quantum Computing | F11: Journal | G11: 10.32604/jqc.2021.025373 | H11: N | I11: N | J11: Y | K11: Y | L11: N | M11: Y | N11: Embedded | Q11: SVM, DT, MLP/ANN/DNN, CNN | R11: Y | S11: UNSW-NB15, Bot-IoT | T11: 2 | U11: N | V11: N | W11: Both | Z11: =IF(AND(ISNUMBER(X11),ISNUMBER(Y11),X11>0),1-Y11/X11,"") | AA11: Not stated | AB11: Unclear | AC11: N | AD11: N | AE11: 68.11 | AF11: =IF(ISNUMBER(AE11),IF(AE11>99,"Y","N"),"") -> N | AG11: N | AH11: N | AI11: N | AJ11: N | AK11: Y | AL11: N | AM11: N | AN11: N | AO11: N | AP11: N | AQ11: N | AR11: N | AS11: N | AU11: rec_id R0162
A12: S011 | B12: Montassar Aidi Sharif | C12: 2022 | D12: A Mechatronics System based on Feature Selection and AI for IoT Intrusion Detection Applications | E12: International Journal of Integrated Engineering | F12: Journal | G12: 10.30880/ijie.2022.14.06.026 | H12: N | I12: N | J12: Y | K12: N | L12: N | M12: Y | N12: Embedded | Q12: kNN, MLP/ANN/DNN, CNN | R12: Y | S12: Private/unspecified | T12: 1 | U12: Y | V12: N | W12: Binary | Z12: =IF(AND(ISNUMBER(X12),ISNUMBER(Y12),X12>0),1-Y12/X12,"") | AA12: Not stated | AB12: Unclear | AC12: N | AD12: Y | AF12: =IF(ISNUMBER(AE12),IF(AE12>99,"Y","N"),"") | AG12: N | AH12: N | AI12: N | AJ12: Y | AK12: N | AL12: N | AM12: N | AN12: N | AO12: N | AP12: N | AQ12: N | AR12: N | AS12: N | AU12: rec_id R0204
A13: S012 | B13: Ahmed Fahad Alshudukhi; Saif Ahmed Jabbar; Basel Alshaikhdeeb | C13: 2022 | D13: A feature selection method based on auto-encoder for internet of things intrusion detection | E13: International Journal of Power Electronics and Drive Systems/International Journal of Electrical and Computer Engineering | F13: Journal | G13: 10.11591/ijece.v12i3.pp3265-3275 | H13: N | I13: Y | J13: Y | K13: N | L13: N | M13: N | N13: Transformation | Q13: SVM, DT, kNN | R13: N | S13: UNSW-NB15 | T13: 1 | U13: N | V13: N | W13: Binary | X13: 198 | Y13: 1 | Z13: =IF(AND(ISNUMBER(X13),ISNUMBER(Y13),X13>0),1-Y13/X13,"") -> 0.99494949 | AA13: Not stated | AB13: Unclear | AC13: N | AD13: N | AE13: 99.97 | AF13: =IF(ISNUMBER(AE13),IF(AE13>99,"Y","N"),"") -> Y | AG13: Y | AH13: N | AI13: N | AJ13: N | AK13: N | AL13: N | AM13: N | AN13: N | AO13: N | AP13: N | AQ13: N | AR13: N | AS13: N | AU13: rec_id R0213
A14: S013 | B14: Kalaivani Kaliyaperumal; M. Chinnadurai; Deepan Perumal; Ganesh Jayaraman; Kannan Samikannu | C14: 2022 | D14: Combined Ensemble Intrusion Detection Model using Deep learning with Feature Selection for Fog Computing Environments | E14: Acta Scientiarum. Technology/Acta scientiarum. Technology | F14: Journal | G14: 10.4025/actascitechnol.v45i1.60551 | H14: N | I14: Y | J14: Y | K14: Y | L14: N | M14: N | N14: Embedded | Q14: RF, SVM, DT, kNN, NB, MLP/ANN/DNN, CNN, LSTM/GRU/RNN | R14: Y | S14: NSL-KDD, KDD Cup 99, UNSW-NB15 | T14: 3 | U14: N | V14: N | W14: Both | X14: 9 | Y14: 1 | Z14: =IF(AND(ISNUMBER(X14),ISNUMBER(Y14),X14>0),1-Y14/X14,"") -> 0.88888889 | AA14: Not stated | AB14: Unclear | AC14: N | AD14: N | AE14: 97.5 | AF14: =IF(ISNUMBER(AE14),IF(AE14>99,"Y","N"),"") -> N | AG14: Y | AH14: Y | AI14: N | AJ14: Y | AK14: Y | AL14: N | AM14: N | AN14: N | AO14: N | AP14: N | AQ14: N | AR14: N | AS14: N | AU14: rec_id R0244
A15: S014 | B15: A. Padmashree; M. Krishnamoorthi | C15: 2022 | D15: Decision Tree with Pearson Correlation-based Recursive Feature Elimination Model for Attack Detection in IoT Environment | E15: Information Technology and Control | F15: Journal | G15: 10.5755/j01.itc.51.4.31818 | H15: Y | I15: Y | J15: Y | K15: N | L15: N | M15: Y | N15: Hybrid | Q15: RF, SVM, DT, kNN, MLP/ANN/DNN, CNN | R15: Y | S15: Bot-IoT | T15: 1 | U15: N | V15: N | Z15: =IF(AND(ISNUMBER(X15),ISNUMBER(Y15),X15>0),1-Y15/X15,"") | AA15: Not stated | AB15: Unclear | AC15: N | AD15: Y | AE15: 99.2 | AF15: =IF(ISNUMBER(AE15),IF(AE15>99,"Y","N"),"") -> Y | AG15: Y | AH15: N | AI15: N | AJ15: Y | AK15: Y | AL15: N | AM15: N | AN15: N | AO15: N | AP15: N | AQ15: N | AR15: N | AS15: N | AU15: rec_id R0247
A16: S015 | B16: D. Dasari; G. Bindu | C16: 2022 | D16: Feature Selection Model-based Intrusion Detection System for Cyberattacks on the Internet of Vehicles Using Cat and Mouse Optimizer | E16: J. Wirel. Mob. Networks Ubiquitous Comput. Dependable Appl. | F16: Journal | G16: 10.58346/jowua.2024.i2.017 | H16: Y | I16: N | J16: Y | K16: N | L16: N | M16: Y | N16: Wrapper-meta | Q16: RF, DT, LSTM/GRU/RNN | R16: Y | S16: CSE-CIC-IDS2018, Car-Hacking | T16: 2 | U16: N | V16: N | W16: Binary | Z16: =IF(AND(ISNUMBER(X16),ISNUMBER(Y16),X16>0),1-Y16/X16,"") | AA16: Not stated | AB16: Unclear | AC16: N | AD16: N | AE16: 99.5 | AF16: =IF(ISNUMBER(AE16),IF(AE16>99,"Y","N"),"") -> Y | AG16: Y | AH16: Y | AI16: N | AJ16: N | AK16: Y | AL16: N | AM16: N | AN16: N | AO16: N | AP16: N | AQ16: N | AR16: N | AS16: N | AU16: rec_id R0268
A17: S016 | B17: S. Balaji; S. Sankaranarayanan | C17: 2022 | D17: Hybrid Deep-GAN Model for Intrusion Detection in IoT Through Enhanced Whale Optimization | E17: International Journal of Computing | F17: Journal | G17: 10.47839/ijc.21.4.2781 | H17: Y | I17: Y | J17: Y | K17: N | L17: Y | M17: Y | N17: Wrapper-meta | Q17: MLP/ANN/DNN, CNN | R17: Y | S17: Private/unspecified | T17: 1 | U17: Y | V17: N | Z17: =IF(AND(ISNUMBER(X17),ISNUMBER(Y17),X17>0),1-Y17/X17,"") | AA17: Not stated | AB17: Unclear | AC17: Y | AD17: N | AF17: =IF(ISNUMBER(AE17),IF(AE17>99,"Y","N"),"") | AG17: Y | AH17: N | AI17: N | AJ17: Y | AK17: N | AL17: N | AM17: N | AN17: N | AO17: N | AP17: N | AQ17: N | AR17: N | AS17: N | AU17: rec_id R0278
A18: S017 | B18: Mashael M. Asiri; Heba G. Mohamed; Mohamed K. Nour; Mesfer Al Duhayyim; Amira Sayed A. Aziz; Abdelwahed Motwakel; Abu Sarwar Zamani; Mohamed I. Eldesouki | C18: 2022 | D18: Hybrid Metaheuristics Feature Selection with Stacked Deep Learning-Enabled Cyber-Attack Detection Model | E18: Computer Systems Science and Engineering | F18: Journal | G18: 10.32604/csse.2023.031063 | H18: N | I18: N | J18: Y | K18: N | L18: N | M18: Y | N18: Wrapper-meta | Q18: SVM, MLP/ANN/DNN, LSTM/GRU/RNN | R18: Y | S18: Private/unspecified | T18: 1 | U18: Y | V18: N | W18: Binary | Z18: =IF(AND(ISNUMBER(X18),ISNUMBER(Y18),X18>0),1-Y18/X18,"") | AA18: Not stated | AB18: Unclear | AC18: N | AD18: N | AF18: =IF(ISNUMBER(AE18),IF(AE18>99,"Y","N"),"") | AG18: N | AH18: N | AI18: N | AJ18: N | AK18: N | AL18: N | AM18: N | AN18: N | AO18: N | AP18: N | AQ18: N | AR18: N | AS18: N | AU18: rec_id R0280
A19: S018 | B19: Sasikumar Gurumurthy; D. Pamela; Upendra Roy | C19: 2022 | D19: Hybrid Pigeon Inspired Optimizer-Gray Wolf Optimization for Network Intrusion Detection | E19: Journal of system and management sciences | F19: Journal | G19: 10.33168/jsms.2022.0423 | H19: N | I19: N | J19: Y | K19: N | L19: N | M19: Y | N19: Wrapper-meta | Q19: SVM | R19: N | S19: NSL-KDD | T19: 1 | U19: Y | V19: N | W19: Both | Z19: =IF(AND(ISNUMBER(X19),ISNUMBER(Y19),X19>0),1-Y19/X19,"") | AA19: Not stated | AB19: Unclear | AC19: N | AD19: Y | AE19: 96.94 | AF19: =IF(ISNUMBER(AE19),IF(AE19>99,"Y","N"),"") -> N | AG19: Y | AH19: N | AI19: N | AJ19: Y | AK19: N | AL19: N | AM19: N | AN19: N | AO19: N | AP19: N | AQ19: N | AR19: N | AS19: N | AU19: rec_id R0281
A20: S019 | B20: S. Vanitha; Palanisamy Balasubramanie | C20: 2022 | D20: Improved Ant Colony Optimization and Machine Learning Based Ensemble Intrusion Detection Model | E20: Intelligent Automation & Soft Computing | F20: Journal | G20: 10.32604/iasc.2023.032324 | H20: Y | I20: N | J20: Y | K20: N | L20: N | M20: N | N20: Wrapper-meta | Q20: SVM, DT | R20: N | S20: UNSW-NB15 | T20: 1 | U20: N | V20: N | W20: Binary | Z20: =IF(AND(ISNUMBER(X20),ISNUMBER(Y20),X20>0),1-Y20/X20,"") | AA20: Not stated | AB20: Unclear | AC20: Y | AD20: N | AF20: =IF(ISNUMBER(AE20),IF(AE20>99,"Y","N"),"") | AG20: Y | AH20: Y | AI20: N | AJ20: Y | AK20: N | AL20: N | AM20: N | AN20: N | AO20: N | AP20: N | AQ20: N | AR20: N | AS20: N | AU20: rec_id R0287
A21: S020 | B21: Reem Ibrahim Alkanhel; El‐Sayed M. El‐kenawy; Abdelaziz A. Abdelhamid; Abdelhameed F. Ibrahim; Manal Abdullah Alohali; Mostafa Salaheldin Abdelsalam Abotaleb; Doaa Sami Khafaga | C21: 2022 | D21: Network Intrusion Detection Based on Feature Selection and Hybrid Metaheuristic Optimization | E21: Computers, materials & continua/Computers, materials & continua (Print) | F21: Journal | G21: 10.32604/cmc.2023.033273 | H21: N | I21: N | J21: Y | K21: N | L21: N | M21: N | N21: Wrapper-meta | Q21: kNN | R21: N | S21: Private/unspecified | T21: 1 | U21: Y | V21: N | W21: Binary | Z21: =IF(AND(ISNUMBER(X21),ISNUMBER(Y21),X21>0),1-Y21/X21,"") | AA21: Not stated | AB21: Unclear | AC21: N | AD21: N | AF21: =IF(ISNUMBER(AE21),IF(AE21>99,"Y","N"),"") | AG21: N | AH21: N | AI21: Y | AJ21: N | AK21: N | AL21: N | AM21: N | AN21: N | AO21: N | AP21: N | AQ21: N | AR21: N | AS21: N | AU21: rec_id R0319
A22: S021 | B22: Fei ZHANG; Peining Zhen; Dishan Jing; Xiaotang Tang; Hai‐Bao Chen; Jie YAN | C22: 2022 | D22: SVM Based Intrusion Detection Method with Nonlinear Scaling and Feature Selection | E22: IEICE Transactions on Information and Systems | F22: Journal | G22: 10.1587/transinf.2021edp7184 | H22: Y | I22: N | J22: N | K22: N | L22: N | M22: Y | N22: Transformation | Q22: SVM, MLP/ANN/DNN, CNN | R22: Y | S22: NSL-KDD | T22: 1 | U22: Y | V22: N | W22: Both | X22: 41 | Y22: 23 | Z22: =IF(AND(ISNUMBER(X22),ISNUMBER(Y22),X22>0),1-Y22/X22,"") -> 0.43902439 | AA22: k-fold CV | AB22: Unclear | AC22: N | AD22: Y | AE22: 82.2 | AF22: =IF(ISNUMBER(AE22),IF(AE22>99,"Y","N"),"") -> N | AG22: Y | AH22: Y | AI22: N | AJ22: Y | AK22: Y | AL22: N | AM22: N | AN22: N | AO22: N | AP22: N | AQ22: N | AR22: N | AS22: N | AU22: rec_id R0341
A23: S022 | B23: Ruqaya Abed Alhasan; Ekhlas Kadhum Hamza | C23: 2023 | D23: A Novel CNN Model with Dimensionality Reduction for WSN Intrusion Detection | E23: Revue d intelligence artificielle | F23: Journal | G23: 10.18280/ria.370504 | H23: Y | I23: N | J23: Y | K23: N | L23: N | M23: Y | N23: Transformation | Q23: RF, SVM, DT, MLP/ANN/DNN, CNN | R23: Y | S23: UNSW-NB15, WSN-DS | T23: 2 | U23: N | V23: N | W23: Multi-class | Y23: 13 | Z23: =IF(AND(ISNUMBER(X23),ISNUMBER(Y23),X23>0),1-Y23/X23,"") | AA23: Single hold-out | AB23: Unclear | AC23: N | AD23: Y | AE23: 99.99 | AF23: =IF(ISNUMBER(AE23),IF(AE23>99,"Y","N"),"") -> Y | AG23: Y | AH23: N | AI23: N | AJ23: Y | AK23: N | AL23: Y | AM23: N | AN23: N | AO23: N | AP23: N | AQ23: N | AR23: N | AS23: N | AU23: rec_id R0364
A24: S023 | B24: Yakub Kayode Saheed; Aisha Abubakar Usman; Favour Dirwokmwa Sukat; Muftahu Abdulrahman | C24: 2023 | D24: A novel hybrid autoencoder and modified particle swarm optimization feature selection for intrusion detection in the internet of things network | E24: Frontiers in Computer Science | F24: Journal | G24: 10.3389/fcomp.2023.997159 | H24: N | I24: N | J24: Y | K24: N | L24: Y | M24: Y | N24: Hybrid | Q24: RF, SVM, DT, kNN, LightGBM, MLP/ANN/DNN, LSTM/GRU/RNN, Autoencoder | R24: Y | S24: NSL-KDD, KDD Cup 99, UNSW-NB15, Bot-IoT | T24: 4 | U24: N | V24: N | W24: Both | Z24: =IF(AND(ISNUMBER(X24),ISNUMBER(Y24),X24>0),1-Y24/X24,"") | AA24: k-fold CV | AB24: Unclear | AC24: Y | AD24: N | AE24: 99.9 | AF24: =IF(ISNUMBER(AE24),IF(AE24>99,"Y","N"),"") -> Y | AG24: Y | AH24: N | AI24: N | AJ24: Y | AK24: Y | AL24: Y | AM24: Y | AN24: N | AO24: N | AP24: N | AQ24: N | AR24: N | AS24: N | AU24: rec_id R0386
A25: S024 | B25: Vijay Prakash Sharma; Narendra Singh Yadav; Sundar Suhrith Adavi; D. Sikha Datta Reddy; Brij Bhooshan Gupta | C25: 2023 | D25: A two stage hybrid intrusion detection using genetic algorithm in IoT networks | E25: Journal of Discrete Mathematical Sciences and Cryptography | F25: Journal | G25: 10.47974/jdmsc-1737 | H25: N | I25: N | J25: Y | K25: N | L25: N | M25: N | N25: Wrapper-meta | Q25: kNN, CNN, LSTM/GRU/RNN | R25: Y | S25: UNSW-NB15 | T25: 1 | U25: N | V25: N | W25: Both | Z25: =IF(AND(ISNUMBER(X25),ISNUMBER(Y25),X25>0),1-Y25/X25,"") | AA25: Not stated | AB25: Unclear | AC25: N | AD25: Y | AF25: =IF(ISNUMBER(AE25),IF(AE25>99,"Y","N"),"") | AG25: N | AH25: N | AI25: N | AJ25: N | AK25: N | AL25: N | AM25: N | AN25: N | AO25: N | AP25: N | AQ25: N | AR25: N | AS25: N | AU25: rec_id R0388
A26: S025 | B26: Demóstenes Zegarra Rodríguez; Ogobuchi Daniel Okey; Siti Sarah Maidin; Ekikere Umoren Udo; João Henrique Kleinschmidt | C26: 2023 | D26: Attentive transformer deep learning algorithm for intrusion detection on IoT systems using automatic Xplainable feature selection | E26: PLoS ONE | F26: Journal | G26: 10.1371/journal.pone.0286652 | H26: Y | I26: N | J26: N | K26: Y | L26: N | M26: Y | N26: Embedded | Q26: DT, XGBoost, MLP/ANN/DNN, CNN, LSTM/GRU/RNN, Transformer/Attention | R26: Y | S26: CICIDS2017, CSE-CIC-IDS2018, CIC-DDoS2019 | T26: 3 | U26: Y | V26: N | W26: Multi-class | Z26: =IF(AND(ISNUMBER(X26),ISNUMBER(Y26),X26>0),1-Y26/X26,"") | AA26: k-fold CV | AB26: Unclear | AC26: Y | AD26: Y | AE26: 97 | AF26: =IF(ISNUMBER(AE26),IF(AE26>99,"Y","N"),"") -> N | AG26: N | AH26: N | AI26: N | AJ26: Y | AK26: Y | AL26: N | AM26: N | AN26: N | AO26: N | AP26: N | AQ26: Y | AR26: N | AS26: N | AU26: rec_id R0418
A27: S026 | B27: Mehmet Bozdal; K. Ileri; Ali Özkahraman | C27: 2023 | D27: Comparative analysis of dimensionality reduction techniques for cybersecurity in the SWaT dataset | E27: Journal of Supercomputing | F27: Journal | G27: 10.1007/s11227-023-05511-w | H27: N | I27: N | J27: N | K27: N | L27: N | M27: Y | N27: Transformation | Q27: DT, CNN, LSTM/GRU/RNN, Autoencoder | R27: Y | S27: SWaT | T27: 1 | U27: N | V27: N | W27: Binary | X27: 100 | Y27: 1 | Z27: =IF(AND(ISNUMBER(X27),ISNUMBER(Y27),X27>0),1-Y27/X27,"") -> 0.99 | AA27: Not stated | AB27: Unclear | AC27: N | AD27: N | AE27: 98.69 | AF27: =IF(ISNUMBER(AE27),IF(AE27>99,"Y","N"),"") -> N | AG27: Y | AH27: N | AI27: N | AJ27: Y | AK27: N | AL27: N | AM27: N | AN27: N | AO27: N | AP27: N | AQ27: N | AR27: N | AS27: N | AU27: rec_id R0431
A28: S027 | B28: Archana Potnurwar; Vrushali K. Bongirwar; Samir N. Ajani; Prof. Nilesh Shelke; Mrunalee Dhone; Namita Parati | C28: 2023 | D28: Deep Learning-Based Rule-Based Feature Selection for Intrusion Detection in Industrial Internet of Things Networks | E28: International Journal of Intelligent Systems and Applications in Engineering | F28: Journal | H28: Y | I28: N | J28: N | K28: N | L28: Y | M28: Y | N28: Hybrid | Q28: RF, CNN | R28: Y | S28: NSL-KDD, UNSW-NB15 | T28: 2 | U28: N | V28: N | Z28: =IF(AND(ISNUMBER(X28),ISNUMBER(Y28),X28>0),1-Y28/X28,"") | AA28: Not stated | AB28: Unclear | AC28: N | AD28: N | AE28: 98.12 | AF28: =IF(ISNUMBER(AE28),IF(AE28>99,"Y","N"),"") -> N | AG28: Y | AH28: N | AI28: N | AJ28: N | AK28: N | AL28: N | AM28: N | AN28: N | AO28: N | AP28: N | AQ28: N | AR28: N | AS28: N | AU28: rec_id R0442
A29: S028 | B29: Ahmed S. Almasoud | C29: 2023 | D29: Enhanced Metaheuristics with Machine Learning Enabled Cyberattack Detection Model | E29: Intelligent Automation & Soft Computing | F29: Journal | G29: 10.32604/iasc.2023.039718 | H29: Y | I29: N | J29: Y | K29: N | L29: N | M29: Y | N29: Wrapper-meta | Q29: RF, SVM, DT, kNN, NB, LightGBM, MLP/ANN/DNN, CNN | R29: Y | S29: UNSW-NB15 | T29: 1 | U29: N | V29: N | W29: Multi-class | Z29: =IF(AND(ISNUMBER(X29),ISNUMBER(Y29),X29>0),1-Y29/X29,"") | AA29: k-fold CV | AB29: Unclear | AC29: N | AD29: N | AF29: =IF(ISNUMBER(AE29),IF(AE29>99,"Y","N"),"") | AG29: N | AH29: Y | AI29: N | AJ29: Y | AK29: N | AL29: N | AM29: N | AN29: N | AO29: N | AP29: N | AQ29: N | AR29: N | AS29: N | AU29: rec_id R0457
A30: S029 | B30: Universiti Tun Hussein Onn Malaysia; Sharifah Shahmim Syed Othman; Cik Feresa Mohd Foozy; Universiti Tun Hussein Onn Malaysia; Siti Noor Baini Mustafa; Book Hack Enterprise | C30: 2023 | D30: Feature Selection of Distributed Denial of Service (DDos) IoT Bot Attack Detection Using Machine Learning Techniques | E30: Journal of Soft Computing and Data Mining | F30: Journal | G30: 10.30880/jscdm.2023.04.01.006 | H30: Y | I30: N | J30: N | K30: N | L30: N | M30: N | N30: Filter | Q30: RF, DT, kNN, NB | R30: N | S30: Bot-IoT, TON_IoT | T30: 2 | U30: N | V30: N | Y30: 4 | Z30: =IF(AND(ISNUMBER(X30),ISNUMBER(Y30),X30>0),1-Y30/X30,"") | AA30: k-fold CV | AB30: Unclear | AC30: N | AD30: N | AE30: 97.506 | AF30: =IF(ISNUMBER(AE30),IF(AE30>99,"Y","N"),"") -> N | AG30: N | AH30: N | AI30: N | AJ30: N | AK30: Y | AL30: N | AM30: N | AN30: N | AO30: N | AP30: N | AQ30: N | AR30: N | AS30: N | AU30: rec_id R0475
A31: S030 | B31: USIC&T, G.G.S.I.P.U, New Delhi, India; Richa Singh; R. L. Ujjwal; USIC&T, G.G.S.I.P.U, New Delhi, India | C31: 2023 | D31: Feature selection using bio-inspired optimization for IoT intrusion detection and prevention system | E31: International Journal on Information Technologies and Security | F31: Journal | G31: 10.59035/oexi6498 | H31: N | I31: N | J31: Y | K31: N | L31: N | M31: N | N31: Wrapper-meta | Q31: XGBoost | R31: N | S31: Bot-IoT, IoTID20 | T31: 2 | U31: N | V31: N | W31: Multi-class | Z31: =IF(AND(ISNUMBER(X31),ISNUMBER(Y31),X31>0),1-Y31/X31,"") | AA31: Not stated | AB31: Unclear | AC31: N | AD31: N | AE31: 99.8 | AF31: =IF(ISNUMBER(AE31),IF(AE31>99,"Y","N"),"") -> Y | AG31: N | AH31: N | AI31: N | AJ31: Y | AK31: N | AL31: N | AM31: N | AN31: N | AO31: N | AP31: N | AQ31: N | AR31: N | AS31: N | AU31: rec_id R0477
A32: S031 | B32: Rekha Gangula; Murali Mohan Vutukuru; Ranjeeth Kumar M. | C32: 2023 | D32: Hybridization of Bottlenose Dolphin Optimization and Artificial Fish Swarm Algorithm with Efficient Classifier for Detecting the Network Intrusion in Internet of Things (IoT) | E32: International Journal of Intelligent Systems and Applications in Engineering | F32: Journal | H32: Y | I32: N | J32: Y | K32: N | L32: Y | M32: Y | N32: Wrapper-meta | Q32: kNN, MLP/ANN/DNN, CNN, LSTM/GRU/RNN | R32: Y | S32: NSL-KDD, UNSW-NB15 | T32: 2 | U32: N | V32: N | W32: Both | Z32: =IF(AND(ISNUMBER(X32),ISNUMBER(Y32),X32>0),1-Y32/X32,"") | AA32: Not stated | AB32: Unclear | AC32: N | AD32: N | AE32: 92 | AF32: =IF(ISNUMBER(AE32),IF(AE32>99,"Y","N"),"") -> N | AG32: Y | AH32: N | AI32: N | AJ32: Y | AK32: N | AL32: N | AM32: N | AN32: N | AO32: N | AP32: N | AQ32: N | AR32: N | AS32: N | AU32: rec_id R0490
A33: S032 | B33: Vu-Duc Ngo; Tuan-Cuong Vuong; Thien van Luong; H. Tran | C33: 2023 | D33: Machine learning-based intrusion detection: feature selection versus feature extraction | E33: Cluster Computing | F33: Journal | G33: 10.1007/s10586-023-04089-5 | H33: Y | I33: N | J33: Y | K33: N | L33: Y | M33: Y | N33: Filter | Q33: RF, SVM, DT, NB, MLP/ANN/DNN, LSTM/GRU/RNN, Autoencoder | R33: Y | S33: UNSW-NB15 | T33: 1 | U33: N | V33: N | W33: Both | Z33: =IF(AND(ISNUMBER(X33),ISNUMBER(Y33),X33>0),1-Y33/X33,"") | AA33: Not stated | AB33: Unclear | AC33: N | AD33: Y | AF33: =IF(ISNUMBER(AE33),IF(AE33>99,"Y","N"),"") | AG33: N | AH33: Y | AI33: N | AJ33: Y | AK33: Y | AL33: N | AM33: N | AN33: N | AO33: N | AP33: N | AQ33: N | AR33: N | AS33: N | AU33: rec_id R0534
A34: S033 | B34: Rekha Gangula; Murali Mohan Vutukuru; Ranjeeth Kumar M | C34: 2023 | D34: Network Intrusion Detection Method Using Stacked BILSTM Elastic Regression Classifier with Aquila Optimizer Algorithm for Internet of Things (IoT) | E34: International Journal on Recent and Innovation Trends in Computing and Communication | F34: Journal | G34: 10.17762/ijritcc.v11i2s.6035 | H34: N | I34: N | J34: Y | K34: Y | L34: N | M34: N | N34: Wrapper-meta | Q34: MLP/ANN/DNN, CNN, LSTM/GRU/RNN | R34: Y | S34: NSL-KDD, UNSW-NB15 | T34: 2 | U34: N | V34: N | W34: Both | Z34: =IF(AND(ISNUMBER(X34),ISNUMBER(Y34),X34>0),1-Y34/X34,"") | AA34: Not stated | AB34: Unclear | AC34: N | AD34: N | AE34: 97.2 | AF34: =IF(ISNUMBER(AE34),IF(AE34>99,"Y","N"),"") -> N | AG34: N | AH34: Y | AI34: N | AJ34: N | AK34: N | AL34: N | AM34: N | AN34: N | AO34: N | AP34: N | AQ34: N | AR34: N | AS34: N | AU34: rec_id R0542
A35: S034 | C35: 2023 | D35: Oppositional Coyote Optimization based Feature Selection with Deep Learning Model for Intrusion Detection in Fog-Assisted Wireless Sensor Network | E35: Acta Montanistica Slovaca | F35: Journal | G35: 10.46544/ams.v28i2.18 | H35: N | I35: N | J35: Y | K35: N | L35: N | M35: N | N35: Wrapper-meta | Q35: SVM, DT, AdaBoost, LSTM/GRU/RNN | R35: Y | S35: KDD Cup 99 | T35: 1 | U35: Y | V35: N | Z35: =IF(AND(ISNUMBER(X35),ISNUMBER(Y35),X35>0),1-Y35/X35,"") | AA35: Not stated | AB35: Unclear | AC35: N | AD35: N | AF35: =IF(ISNUMBER(AE35),IF(AE35>99,"Y","N"),"") | AG35: N | AH35: N | AI35: N | AJ35: Y | AK35: N | AL35: N | AM35: N | AN35: N | AO35: N | AP35: N | AQ35: N | AR35: N | AS35: N | AU35: rec_id R0544
A36: S035 | B36: Moody Alhanaya; K. Al-Shqeerat | C36: 2023 | D36: Performance Analysis of Intrusion Detection System in the IoT Environment Using Feature Selection Technique | E36: Intelligent Automation and Soft Computing | F36: Journal | G36: 10.32604/iasc.2023.036856 | H36: N | I36: N | J36: N | K36: Y | L36: N | M36: Y | N36: Embedded | Q36: RF, SVM, kNN | R36: N | S36: UNSW-NB15, Bot-IoT | T36: 2 | U36: N | V36: N | W36: Binary | Z36: =IF(AND(ISNUMBER(X36),ISNUMBER(Y36),X36>0),1-Y36/X36,"") | AA36: k-fold CV | AB36: Unclear | AC36: N | AD36: N | AF36: =IF(ISNUMBER(AE36),IF(AE36>99,"Y","N"),"") | AG36: N | AH36: N | AI36: N | AJ36: N | AK36: N | AL36: N | AM36: N | AN36: N | AO36: N | AP36: N | AQ36: N | AR36: N | AS36: N | AU36: rec_id R0555
A37: S036 | B37: Mohammed Sayeeduddin Habeeb; Tummala Ranga Babu | C37: 2024 | D37: A Two-Phase Feature Selection Technique using Information Gain and XGBoost-RFE for NIDS | E37: International Journal of Intelligent Systems and Applications in Engineering | F37: Journal | H37: Y | I37: Y | J37: N | K37: Y | L37: N | M37: N | N37: Hybrid | Q37: XGBoost, MLP/ANN/DNN, CNN, LSTM/GRU/RNN | R37: Y | S37: Bot-IoT | T37: 1 | U37: N | V37: N | W37: Binary | Y37: 16 | Z37: =IF(AND(ISNUMBER(X37),ISNUMBER(Y37),X37>0),1-Y37/X37,"") | AA37: Single hold-out | AB37: Unclear | AC37: N | AD37: Y | AE37: 99.8 | AF37: =IF(ISNUMBER(AE37),IF(AE37>99,"Y","N"),"") -> Y | AG37: Y | AH37: N | AI37: N | AJ37: N | AK37: N | AL37: N | AM37: N | AN37: N | AO37: N | AP37: N | AQ37: N | AR37: N | AS37: N | AU37: rec_id R0619
A38: S037 | B38: Hamdullah Karamollaoğlu; İbrahim Alper Doğru; İbrahim Yücedağ | C38: 2024 | D38: An Efficient Deep Learningbased Intrusion Detection System for Internet of Things Networks with Hybrid Feature Reduction and Data Balancing Techniques | E38: Information Technology And Control | F38: Journal | G38: 10.5755/j01.itc.53.1.34933 | H38: N | I38: N | J38: Y | K38: N | L38: N | M38: Y | N38: Hybrid | Q38: SVM, kNN, NB, LR, AdaBoost, CNN, LSTM/GRU/RNN | R38: Y | S38: Bot-IoT, IoTID20 | T38: 2 | U38: N | V38: N | W38: Multi-class | X38: 84 | Y38: 34 | Z38: =IF(AND(ISNUMBER(X38),ISNUMBER(Y38),X38>0),1-Y38/X38,"") -> 0.5952381 | AA38: k-fold CV | AB38: Unclear | AC38: N | AD38: N | AE38: 99.97 | AF38: =IF(ISNUMBER(AE38),IF(AE38>99,"Y","N"),"") -> Y | AG38: Y | AH38: Y | AI38: N | AJ38: Y | AK38: N | AL38: N | AM38: N | AN38: N | AO38: N | AP38: N | AQ38: N | AR38: N | AS38: N | AU38: rec_id R0653
A39: S038 | B39: Pinkey Chauhan; Mithilesh Atulkar | C39: 2024 | D39: An efficient attack detection approach for software defined Internet of Things using Jaya optimisation based feature selection technique | E39: International Journal of Communication Networks and Distributed Systems | F39: Journal | G39: 10.1504/ijcnds.2025.142985 | H39: N | I39: N | J39: Y | K39: N | L39: N | M39: N | N39: Wrapper-meta | Q39: DT, LSTM/GRU/RNN | R39: N | S39: Bot-IoT | T39: 1 | U39: N | V39: N | W39: Both | Y39: 6 | Z39: =IF(AND(ISNUMBER(X39),ISNUMBER(Y39),X39>0),1-Y39/X39,"") | AA39: k-fold CV | AB39: Unclear | AC39: N | AD39: Y | AE39: 98.908 | AF39: =IF(ISNUMBER(AE39),IF(AE39>99,"Y","N"),"") -> N | AG39: Y | AH39: N | AI39: N | AJ39: Y | AK39: Y | AL39: N | AM39: N | AN39: N | AO39: N | AP39: N | AQ39: N | AR39: N | AS39: N | AU39: rec_id R0674
A40: S039 | B40: Ved S. Bilaskar; Shyam V. Aradhye; Snehal S. Shinde; Deepak D. Kshirsagar; Pushparaj R. Nimbalkar | C40: 2024 | D40: An intrusion detection system for industrial IoT using chi-square feature selection | E40: Journal of Statistics and Management Systems | F40: Journal | G40: 10.47974/jsms-1303 | H40: Y | I40: Y | J40: Y | K40: N | L40: N | M40: N | N40: Filter | Q40: SVM | R40: N | S40: UNSW-NB15, Bot-IoT, Edge-IIoTset | T40: 3 | U40: N | V40: N | W40: Both | Y40: 20 | Z40: =IF(AND(ISNUMBER(X40),ISNUMBER(Y40),X40>0),1-Y40/X40,"") | AA40: k-fold CV | AB40: Unclear | AC40: N | AD40: Y | AE40: 97.5202 | AF40: =IF(ISNUMBER(AE40),IF(AE40>99,"Y","N"),"") -> N | AG40: Y | AH40: N | AI40: N | AJ40: N | AK40: Y | AL40: N | AM40: N | AN40: N | AO40: N | AP40: N | AQ40: N | AR40: N | AS40: N | AU40: rec_id R0683
...

Sheet QA
A1: ID | B1: QA1 | C1: QA2 | D1: QA3 | E1: QA4 | F1: QA5 | G1: QA6 | H1: QA7 | I1: QA8 | J1: Total (0–8) | K1: Grade
A2: =Studies!A2 -> S001 | B2: 1 | C2: 0 | D2: 0 | E2: 0.5 | F2: 0.5 | G2: 0 | H2: 0 | I2: 0 | J2: =IF(COUNT(B2:I2)=8,SUM(B2:I2),"") -> 2 | K2: =IF(J2="","",IF(J2>=5,"High",IF(J2>=3.5,"Medium","Low"))) -> Low
A3: =Studies!A3 -> S002 | B3: 1 | C3: 0 | D3: 1 | E3: 0 | F3: 0.5 | G3: 1 | H3: 0 | I3: 0 | J3: =IF(COUNT(B3:I3)=8,SUM(B3:I3),"") -> 3.5 | K3: =IF(J3="","",IF(J3>=5,"High",IF(J3>=3.5,"Medium","Low"))) -> Medium
A4: =Studies!A4 -> S003 | B4: 1 | C4: 0 | D4: 1 | E4: 1 | F4: 1 | G4: 0.5 | H4: 0 | I4: 0 | J4: =IF(COUNT(B4:I4)=8,SUM(B4:I4),"") -> 4.5 | K4: =IF(J4="","",IF(J4>=5,"High",IF(J4>=3.5,"Medium","Low"))) -> Medium
A5: =Studies!A5 -> S004 | B5: 0.5 | C5: 0 | D5: 0 | E5: 0.5 | F5: 0.5 | G5: 0.5 | H5: 0 | I5: 0 | J5: =IF(COUNT(B5:I5)=8,SUM(B5:I5),"") -> 2 | K5: =IF(J5="","",IF(J5>=5,"High",IF(J5>=3.5,"Medium","Low"))) -> Low
A6: =Studies!A6 -> S005 | B6: 0.5 | C6: 0 | D6: 0 | E6: 0.5 | F6: 1 | G6: 0.5 | H6: 0 | I6: 0 | J6: =IF(COUNT(B6:I6)=8,SUM(B6:I6),"") -> 2.5 | K6: =IF(J6="","",IF(J6>=5,"High",IF(J6>=3.5,"Medium","Low"))) -> Low
A7: =Studies!A7 -> S006 | B7: 0.5 | C7: 0 | D7: 0 | E7: 0.5 | F7: 0 | G7: 1 | H7: 1 | I7: 0 | J7: =IF(COUNT(B7:I7)=8,SUM(B7:I7),"") -> 3 | K7: =IF(J7="","",IF(J7>=5,"High",IF(J7>=3.5,"Medium","Low"))) -> Low
A8: =Studies!A8 -> S007 | B8: 0.5 | C8: 0 | D8: 1 | E8: 1 | F8: 0 | G8: 1 | H8: 0 | I8: 0 | J8: =IF(COUNT(B8:I8)=8,SUM(B8:I8),"") -> 3.5 | K8: =IF(J8="","",IF(J8>=5,"High",IF(J8>=3.5,"Medium","Low"))) -> Medium
A9: =Studies!A9 -> S008 | B9: 1 | C9: 0 | D9: 1 | E9: 0.5 | F9: 0.5 | G9: 1 | H9: 0 | I9: 0 | J9: =IF(COUNT(B9:I9)=8,SUM(B9:I9),"") -> 4 | K9: =IF(J9="","",IF(J9>=5,"High",IF(J9>=3.5,"Medium","Low"))) -> Medium
A10: =Studies!A10 -> S009 | B10: 1 | C10: 0 | D10: 1 | E10: 1 | F10: 1 | G10: 1 | H10: 1 | I10: 0 | J10: =IF(COUNT(B10:I10)=8,SUM(B10:I10),"") -> 6 | K10: =IF(J10="","",IF(J10>=5,"High",IF(J10>=3.5,"Medium","Low"))) -> High
A11: =Studies!A11 -> S010 | B11: 0.5 | C11: 0 | D11: 0 | E11: 0.5 | F11: 0 | G11: 0.5 | H11: 1 | I11: 0 | J11: =IF(COUNT(B11:I11)=8,SUM(B11:I11),"") -> 2.5 | K11: =IF(J11="","",IF(J11>=5,"High",IF(J11>=3.5,"Medium","Low"))) -> Low
A12: =Studies!A12 -> S011 | B12: 0.5 | C12: 0 | D12: 0 | E12: 1 | F12: 0 | G12: 0.5 | H12: 0 | I12: 0 | J12: =IF(COUNT(B12:I12)=8,SUM(B12:I12),"") -> 2 | K12: =IF(J12="","",IF(J12>=5,"High",IF(J12>=3.5,"Medium","Low"))) -> Low
A13: =Studies!A13 -> S012 | B13: 1 | C13: 0 | D13: 0 | E13: 0.5 | F13: 0.5 | G13: 0 | H13: 0 | I13: 0 | J13: =IF(COUNT(B13:I13)=8,SUM(B13:I13),"") -> 2 | K13: =IF(J13="","",IF(J13>=5,"High",IF(J13>=3.5,"Medium","Low"))) -> Low
... A131: =Studies!A131 -> S130 | B131: 1 | C131: 0 | D131: 1 | E131: 0.5 | F131: 0.5 | G131: 0.5 | H131: 1 | I131: 0 | J131: =IF(COUNT(B131:I131)=8,SUM(B131:I131),"") -> 4.5 | K131: =IF(J131="","",IF(J131>=5,"High",IF(J131>=3.5,"Medium","Low"))) -> Medium

Sheet Checklist
A1: ID | B1: 1 Dataset & preprocessing | C1: 2 Class setting & imbalance | D1: 3 FS inside training folds | E1: 4 Full FS specification | F1: 5 Selected feature list | G1: 6 Repeated runs mean±sd | H1: 7 Baselines | I1: 8 Class-sensitive metrics | J1: 9 Significance testing | K1: 10 Cost on stated hardware | L1: 11 ≥2 datasets / cross-dataset | M1: 12 Code released | N1: Items met
A2: =Studies!A2 -> S001 | B2: Y | C2: N | D2: N | E2: Y | F2: N | G2: N | H2: N | I2: N | J2: N | K2: N | L2: N | M2: N | N2: =COUNTIF(B2:M2,"Y") -> 2
A3: =Studies!A3 -> S002 | B3: Y | C3: N | D3: N | E3: Y | F3: N | G3: N | H3: N | I3: N | J3: N | K3: Y | L3: N | M3: N | N3: =COUNTIF(B3:M3,"Y") -> 3
A4: =Studies!A4 -> S003 | B4: Y | C4: Y | D4: N | E4: Y | F4: Y | G4: N | H4: Y | I4: Y | J4: N | K4: Y | L4: N | M4: N | N4: =COUNTIF(B4:M4,"Y") -> 7
A5: =Studies!A5 -> S004 | B5: Y | C5: N | D5: N | E5: N | F5: N | G5: N | H5: N | I5: N | J5: N | K5: Y | L5: N | M5: N | N5: =COUNTIF(B5:M5,"Y") -> 2
A6: =Studies!A6 -> S005 | B6: Y | C6: N | D6: N | E6: N | F6: N | G6: N | H6: N | I6: Y | J6: N | K6: N | L6: N | M6: N | N6: =COUNTIF(B6:M6,"Y") -> 2
A7: =Studies!A7 -> S006 | B7: Y | C7: Y | D7: N | E7: N | F7: N | G7: N | H7: N | I7: N | J7: Y | K7: Y | L7: Y | M7: N | N7: =COUNTIF(B7:M7,"Y") -> 5
A8: =Studies!A8 -> S007 | B8: Y | C8: Y | D8: N | E8: N | F8: N | G8: N | H8: Y | I8: N | J8: N | K8: N | L8: N | M8: N | N8: =COUNTIF(B8:M8,"Y") -> 3
A9: =Studies!A9 -> S008 | B9: N | C9: N | D9: N | E9: Y | F9: N | G9: N | H9: N | I9: N | J9: N | K9: N | L9: N | M9: N | N9: =COUNTIF(B9:M9,"Y") -> 1
A10: =Studies!A10 -> S009 | B10: Y | C10: Y | D10: N | E10: Y | F10: N | G10: N | H10: Y | I10: Y | J10: N | K10: Y | L10: Y | M10: N | N10: =COUNTIF(B10:M10,"Y") -> 7
A11: =Studies!A11 -> S010 | B11: Y | C11: Y | D11: N | E11: N | F11: N | G11: N | H11: N | I11: N | J11: N | K11: N | L11: Y | M11: N | N11: =COUNTIF(B11:M11,"Y") -> 3
A12: =Studies!A12 -> S011 | B12: N | C12: N | D12: N | E12: N | F12: N | G12: N | H12: Y | I12: N | J12: N | K12: N | L12: N | M12: N | N12: =COUNTIF(B12:M12,"Y") -> 1
A13: =Studies!A13 -> S012 | B13: Y | C13: N | D13: N | E13: Y | F13: Y | G13: N | H13: N | I13: N | J13: N | K13: N | L13: N | M13: N | N13: =COUNTIF(B13:M13,"Y") -> 3
... A131: =Studies!A131 -> S130 | B131: Y | C131: Y | D131: N | E131: Y | F131: N | G131: Y | H131: N | I131: N | J131: N | K131: N | L131: Y | M131: N | N131: =COUNTIF(B131:M131,"Y") -> 5

Sheet DRL
A1: ID | B1: DRL level
A2: =Studies!A2 -> S001 | B2: DRL-0
A3: =Studies!A3 -> S002 | B3: DRL-0
A4: =Studies!A4 -> S003 | B4: DRL-0
A5: =Studies!A5 -> S004 | B5: DRL-0
A6: =Studies!A6 -> S005 | B6: DRL-0
A7: =Studies!A7 -> S006 | B7: DRL-0
A8: =Studies!A8 -> S007 | B8: DRL-0
A9: =Studies!A9 -> S008 | B9: DRL-0
A10: =Studies!A10 -> S009 | B10: DRL-0
A11: =Studies!A11 -> S010 | B11: DRL-0
A12: =Studies!A12 -> S011 | B12: DRL-0
A13: =Studies!A13 -> S012 | B13: DRL-0
... A131: =Studies!A131 -> S130 | B131: DRL-2

Sheet PRISMA
A1: Item | B1: Count | C1: Notes
A2: OpenAlex hits | B2: 922
A3: Semantic Scholar hits | B3: 1399
A4: — | B4: 0
A5: — | B5: 0
A6: — | B6: 0
A7: — | B7: 0
A8: Records identified (total) | B8: =SUM(B2:B7) -> 2321
A9: Duplicates removed | B9: 676
A10: Records excluded at title/abstract | B10: 1139
A11: Full texts excluded: EC1 (not IoT 2, not IDS 1) | B11: 3
A12: Full texts excluded: EC2 (extraction only) | B12: 0
A13: Full texts excluded: EC3 (no experiments/dataset) | B13: 1
A14: Full texts excluded: retracted (1) or non-English (1) | B14: 2
A15: Reports not retrieved or unreadable | B15: 370
A16: Added by snowballing | B16: 0
A17: Cohen's kappa (title/abstract screening) | B17: n/a (single reviewer)
A18: Search start (month/year) | B18: 2018 (publication years 2018–2025)
A19: Final search date | B19: 22 Oct 2026
A20: Records screened (title/abstract) | B20: =B8-B9 -> 1645
A21: Reports sought for retrieval | B21: =B20-B10 -> 506
A22: Not retrieved/unreadable + full-text exclusions | B22: =SUM(B11:B15) -> 376
A23: Studies included | B23: =B21-B22+B16 -> 130
A24: Check: included should equal 130 | B24: =IF(B23=130,"OK","CHECK") -> OK
